---
title: "Why is my Timeout asyncio.wait_for not taken into account?"
date: "2024-12-15"
id: "why-is-my-timeout-asynciowaitfor-not-taken-into-account"
---

alright, let's break down why your `asyncio.wait_for` might be ignoring your timeout. i've bumped into this gremlin more times than i care to remember, and it usually boils down to a few common gotchas. basically, `asyncio.wait_for` wraps an awaitable, like a coroutine, with a time limit. if that awaitable doesn't finish within the specified timeout, it's supposed to raise an `asyncio.timeoutError` . but things can get tricky when the awaitable itself doesn't play by the rules of cooperatively yielding control to the event loop.

the first thing to think about is that asyncio is cooperative, meaning tasks must voluntarily give up control to let other tasks run. if your awaitable is stuck in a cpu-bound loop or a blocking i/o operation, it won't yield to the event loop, and thus `wait_for` won't get a chance to trigger its timeout. the event loop is basically the referee, and if your task is doing a stubborn one-person show, the referee can't call timeout.

i had this exact issue back in the days when i was crafting this real-time data processing engine. we were pulling data from multiple sources and doing some heavy lifting on the data before pushing it into our database. one of the data sources was occasionally sluggish, and the coroutine that was responsible for fetching from this source would occasionally just hang. we were relying on `wait_for` to stop the program from being stuck in this slow data source. the problem? the http client library that was fetching this data from that source, was a blocking one, so when the connection was slow, it didn't yield. `wait_for` just waited, powerless. here’s a very basic and simplified example to illustrate this behavior:

```python
import asyncio
import time

async def blocking_task():
    print("blocking task started")
    time.sleep(5)  #simulates blocking operation
    print("blocking task finished")
    return "done"

async def main():
    try:
        result = await asyncio.wait_for(blocking_task(), timeout=1)
        print(f"result: {result}")
    except asyncio.TimeoutError:
        print("timeout occurred")

if __name__ == "__main__":
    asyncio.run(main())
```

if you run that, you will see it will not timeout, instead, it waits the entire 5 seconds. even though `asyncio.wait_for` was set to timeout in 1 second. that is because `time.sleep(5)` is a blocking call that doesn't yield control to the event loop. `asyncio.wait_for` is basically waiting for the task to cooperate.

the solution, in that case, was to replace that blocking http client with an asynchronous client library that used `asyncio` under the hood, which was able to yield control when waiting for a response. a good one for you to take a look at, should be aiohttp. it really made all the difference. it's like teaching the task how to play nice with others.

another scenario where `wait_for` might not behave as intended is when you’re using a custom awaitable that doesn’t yield properly. for example, if you’re building your own custom async iterator or context manager that doesn’t have proper `await` points, it could stall the event loop. this is less common, but definitely something to watch for if you’re creating custom async logic.

a few other, more subtle things can lead to `wait_for` not working. if the coroutine is calling another synchronous function that doesn't yield or something that's also blocking, such as a database query that's not asynchronous, you may also be stuck. that’s when the timeout doesn't trigger. it’s basically like a chain of blockages that stop the event loop from doing its work. if you're doing any sort of database interaction it is imperative that it's an async implementation. i had that problem when interacting with a redis instance. it was my fault i had not added `asyncio` support for my client.

the other thing is, if you’re using an event loop from another library or if something else is also managing the loop, like using `asyncio` with some kind of a gui framework, that could also cause weird behaviors with the timeout because the underlying event loop can be somewhat masked. double-check your frameworks to see if they conflict with your `asyncio` event loop.

here’s an example that illustrates a coroutine that yields properly, and how `wait_for` handles it successfully:

```python
import asyncio

async def async_task():
    print("async task started")
    await asyncio.sleep(3)  #yielding and making the loop go on
    print("async task finished")
    return "done"

async def main():
    try:
        result = await asyncio.wait_for(async_task(), timeout=1)
        print(f"result: {result}")
    except asyncio.TimeoutError:
        print("timeout occurred")

if __name__ == "__main__":
    asyncio.run(main())

```

in this one, since we are using `asyncio.sleep(3)` the execution yields to the loop during the 3 seconds and `wait_for` kicks in and raises the exception.

another point worth mentioning is that if a task is already completed when `asyncio.wait_for` is called, then the timeout is not considered. it will simply return immediately. it's basically checking whether the task is done first, and if it is, it is what it is.

and finally, a tricky one i fell into was when a coroutine raised an exception, but the exception was not caught within the task before the `wait_for`, and sometimes `wait_for` just catches the exception before the timeout, and so it might look like it was not working as expected. i'll show a case of what can happen.

```python
import asyncio

async def problematic_async_task():
    print("task started")
    await asyncio.sleep(0.5)
    raise ValueError("something went bad!")

async def main():
    try:
        result = await asyncio.wait_for(problematic_async_task(), timeout=1)
        print(f"result: {result}")
    except asyncio.TimeoutError:
        print("timeout error")
    except ValueError as e:
        print(f"value error: {e}")

if __name__ == "__main__":
    asyncio.run(main())
```
here, if we set a timeout bigger than 0.5, it raises a value error, and it does not get canceled by the `timeout`.

so how do you troubleshoot these? well, the key is to examine your awaitables, step by step, i use print statements as a very last resort. a proper debugger will help. you should make sure all blocking or cpu-bound sections are implemented using async alternatives, such as aiohttp, aioredis, or using a thread pool for cpu-bound operations. if you are using a custom awaitable or iterator you must verify they are properly yielding to the event loop. if that's not possible, then you might have to run that portion using a thread pool using the `asyncio.to_thread` or `concurrent.futures` modules, to avoid blocking the loop. it’s like bringing a translator to a meeting so that everyone can understand each other, the event loop can't communicate with a task that does not yield.

some resources i found very helpful to really nail down these issues were books like “fluent python” by luciano ramalho, especially the sections related to coroutines and asynchronous programming. it offers great insight into how python manages these kinds of things under the hood. also the official python documentation is top-notch, for everything `asyncio`, including the different parts of it, i always make sure to go there first. the section on `asyncio.wait_for` specifically is quite thorough. if you want to go deeper on event loops and asynchronous paradigms you could try books like “operating system concepts” by silberschatz and galvin, which gives a more fundamental view of these mechanics.

remember, the asyncio is all about cooperation. if a task doesn't play by the rules, then the timeout mechanism won’t work. always look for those parts of your code which could be causing a deadlock. make sure that all components are asynchronous and yield control, that's how you can get your `wait_for` to play nicely. the first time it fails it's always a bit of a head-scratcher, but it becomes easier with experience. and when in doubt just print it, it might take a while but in the end, your code will be able to execute smoothly.
