---
title: "Why are DataLoader workers exiting unexpectedly?"
date: "2025-01-30"
id: "why-are-dataloader-workers-exiting-unexpectedly"
---
DataLoader worker exits, especially during PyTorch training, often stem from an unhandled exception within the worker process itself, frequently masked by the multiprocessing framework. These are not typically issues with the main training loop or the DataLoader’s configuration directly, but rather problems localized within the data loading routines executing in these separate processes. Understanding this distinction is crucial to diagnosing and resolving the issue effectively.

My experience with this problem, particularly during a large-scale image segmentation project involving heavily augmented datasets, has shown that the root cause often lies in the subtle ways data preprocessing logic interacts with multiprocessing. The Python `multiprocessing` library, which PyTorch's DataLoader leverages, creates independent processes. When a worker encounters an exception, it typically doesn’t automatically propagate up to the main process like an ordinary Python exception. The default behavior is for the worker process to exit silently, with the DataLoader noticing the missing process when it requests more data. This silent failure makes debugging quite challenging.

The primary reason for this process exit centers around data loading operations or transformations that encounter errors *within the worker process*. This can be anything from corrupt image files, errors in custom transformation functions (those invoked using PyTorch's `torchvision.transforms` or similar), or issues within libraries used for specific file formats. Errors such as `FileNotFoundError`, `IOError`, `ValueError`, or `KeyError`, which might be inconsequential in a single-threaded environment, become terminal when they occur within the context of the worker.

Here’s a breakdown of common problem areas and how to address them, illustrated with examples:

**1. Data Loading and Handling Errors:**

One frequent cause is improper handling of missing or corrupt files. The DataLoader, in its effort to be performant, does not rigorously check each file individually before passing it to the data processing pipeline. If a dataset includes a malformed image, or a file is deleted while a worker is attempting to access it, the worker might abruptly fail. The following code illustrates an error-prone approach:

```python
import torch
from torch.utils.data import Dataset, DataLoader
from PIL import Image
import os

class CustomDataset(Dataset):
    def __init__(self, root_dir):
        self.image_paths = [os.path.join(root_dir, f) for f in os.listdir(root_dir) if f.endswith('.jpg')]
    def __len__(self):
        return len(self.image_paths)

    def __getitem__(self, idx):
        try:
            image_path = self.image_paths[idx]
            image = Image.open(image_path) # Potential FileNotFoundError, OSError, etc.
            image = image.convert("RGB")
            image = torch.tensor(np.array(image).transpose(2,0,1)).float() / 255.0
            return image, torch.ones(1) # Dummy label
        except Exception as e:
            print(f"Error in worker loading {image_path}: {e}")
            return None, None # Return 'None' to signal failure

root_dir = 'images/'  # Assume you have a directory named 'images'
dataset = CustomDataset(root_dir)
dataloader = DataLoader(dataset, batch_size=4, num_workers=2) # Example with two workers

for images, labels in dataloader:
    if images is not None:
        # Proceed with training logic
        print(f"Batch data: {images.shape}")
    else:
        print("Skipping batch due to error.")
```

In this example, using `Image.open()` directly inside the `__getitem__` method can potentially throw exceptions that could kill a worker process, especially with a large diverse dataset. The `try-except` block catches the error, printing information to aid in identifying faulty files and returns `None`. In a production system this will require more robust error handling. A solution might involve logging, or skipping that entry in the dataset, or providing a default value. Simply ignoring the exception may lead to silent failure later on.

**2. Issues within Custom Transformations:**

Custom transformation functions applied within the dataset's `__getitem__` method can also trigger worker exits, especially when they rely on external libraries or perform complex manipulations on data. An improper or unexpected input to such a transform will cause an error to occur in that process and terminate it.

```python
import torch
from torch.utils.data import Dataset, DataLoader
from torchvision import transforms
import numpy as np

class TransformationError(Exception):
    pass

class CustomTransform:
    def __call__(self, image):
        #Assume for now this could be any function which transforms data.

        if not isinstance(image, np.ndarray):
            raise TransformationError("Error in transform - Image not ndarray")
        try:
          return torch.tensor(image + np.random.rand(*image.shape)) # This could result in invalid values
        except Exception as e:
            print(f"Error in custom transform: {e}")
            raise TransformationError("An error occurred within custom transform.")

class CustomDataset(Dataset):
    def __init__(self, root_dir):
        self.image_paths = [os.path.join(root_dir, f) for f in os.listdir(root_dir) if f.endswith('.jpg')]
        self.transform = transforms.Compose([CustomTransform()])

    def __len__(self):
        return len(self.image_paths)

    def __getitem__(self, idx):
       try:
         image_path = self.image_paths[idx]
         image = Image.open(image_path)
         image = image.convert('RGB')
         image = np.array(image)
         transformed_image = self.transform(image)
         return transformed_image, torch.ones(1)
       except Exception as e:
         print(f"Error processing {image_path}: {e}")
         return None, None # or some other error handling method

dataset = CustomDataset('images/')
dataloader = DataLoader(dataset, batch_size=4, num_workers=2)

for images, labels in dataloader:
  if images is not None:
    print(f"Batch data: {images.shape}")
  else:
    print("Skipping batch due to errors")

```

This code demonstrates the problem of exceptions occurring during custom image transformations. Here, the transform class `CustomTransform` applies a small random amount to the image tensor. While this example is rather simplistic, many transforms can have failure points, often related to unexpected or corrupt data, numerical instability, or library usage issues. Again, the `try-except` block in the data loading function prevents the error from causing a crash but logs information and also returns a specific value to indicate a failure.

**3. Concurrency Issues and Shared Resources:**

Less common, but significant, are issues arising from improper handling of shared resources, such as global variables or file handles, across multiple worker processes. While each worker gets its own copy of variables, issues can occur if a global resource is used without proper mechanisms to deal with simultaneous access. Consider a contrived example for demonstration purposes:

```python
import torch
from torch.utils.data import Dataset, DataLoader
import time
import os
import random

GLOBAL_VAR = 0 # Shared state. NOT good practice in worker processes.

class SharedStateDataset(Dataset):
    def __init__(self, root_dir):
      self.image_paths = [os.path.join(root_dir, f) for f in os.listdir(root_dir) if f.endswith('.jpg')]

    def __len__(self):
      return len(self.image_paths)

    def __getitem__(self, idx):
      try:
        image_path = self.image_paths[idx]
        image = Image.open(image_path).convert("RGB")
        image = torch.tensor(np.array(image).transpose(2,0,1)).float()/255.0
        global GLOBAL_VAR
        GLOBAL_VAR += random.randint(1,10) # Modifying the global state can lead to issues.
        time.sleep(0.01)
        return image, torch.ones(1)
      except Exception as e:
          print(f"Error loading {image_path}: {e}")
          return None, None

dataset = SharedStateDataset('images/')
dataloader = DataLoader(dataset, batch_size=4, num_workers=2)

for i,(images, labels) in enumerate(dataloader):
  if images is not None:
      print(f"Batch {i} processed successfully with {images.shape}. Global Variable: {GLOBAL_VAR}")
  else:
      print(f"Skipping batch due to error.")

```

In the above code, the `GLOBAL_VAR` is modified within each worker. This is generally not safe since the workers have separate memory spaces. While in this simple contrived case it will not raise an exception or error, in real applications it can lead to unexpected results when workers are attempting to access and modify a shared object. In a more complex and robust system, race conditions would cause issues. However, in this case we have a shared data structure which is being updated in place, which can have unpredictable results. It will not necessarily cause a worker to crash, but this example highlights one of the potential problems that can exist in a poorly designed data loading pipeline. This is something that requires consideration when designing complex data loading applications.

**Resource Recommendations:**

To improve your understanding of debugging DataLoader workers, several types of resources will prove beneficial.

*   **Documentation:** Deep dive into the official PyTorch documentation related to `torch.utils.data.DataLoader` and the `torch.multiprocessing` module. Pay special attention to the sections concerning worker initialization and error handling.

*   **Multiprocessing Library Guides:** Explore resources that explain Python's `multiprocessing` library in detail. An understanding of concepts like process pools, shared memory, and inter-process communication is important.

*   **Error Handling Best Practices:** Study best practices for exception handling in Python, particularly within a multi-process environment. Learn techniques for logging, recovering from data errors, and designing robust data pipelines.

By focusing on exception handling within data preprocessing logic, careful consideration of custom transforms and avoidance of shared mutable data, you can effectively address the issue of DataLoader workers exiting unexpectedly during PyTorch training. This issue is less of a PyTorch framework issue and more of a problem of proper data loading best practices and proper exception handling in multi-process environments.
