---
title: "Why do Azure Functions exhibit asynchronous errors with `async/Task` that aren't present in Console Apps?"
date: "2025-01-30"
id: "why-do-azure-functions-exhibit-asynchronous-errors-with"
---
The discrepancy in asynchronous error handling between Azure Functions and console applications using `async/await` and `Task` stems primarily from the fundamental differences in their execution environments and how exceptions are propagated.  My experience debugging production-level Azure Functions has highlighted this distinction repeatedly, particularly when dealing with long-running, I/O-bound operations.  Console applications typically run within a single, predictable process, whereas Azure Functions operate within a managed, ephemeral environment, introducing several layers of abstraction that influence exception handling.

**1. Execution Environment Differences:**

A console application executes within a straightforward process managed directly by the operating system.  Unhandled exceptions generally result in immediate termination of the process, with detailed stack traces readily available.  Conversely, Azure Functions operate within a serverless environment. The function's runtime is responsible for managing the lifecycle of the function instance, handling resource allocation, and scaling.  This means unhandled exceptions within a function might not directly terminate the entire application; instead, the runtime might log the error, potentially retry the execution (depending on configuration), or simply move on to the next invocation.  This decoupling significantly alters how exceptions are surfaced and handled.

**2. Host and Worker Processes:**

Azure Functions utilize a host process and worker processes. The host manages the function's environment, while the worker processes execute the function code.  Exceptions occurring within the worker process might not immediately propagate to the host, leading to a delay in error reporting or requiring examination of logs for detailed information.  This contrasts with console apps where the single process provides immediate feedback on exceptions.  In my experience, overlooking this multi-process architecture has been a significant source of debugging challenges with Azure Functions, particularly when dealing with concurrency.

**3. Middleware and Exception Handling:**

Azure Functions provide mechanisms like middleware to intercept and handle exceptions before they reach the function's core logic.  These middleware components can log errors, implement retry policies, or even send notifications. However, improper configuration or unforeseen interactions within middleware can mask the root cause of exceptions, making debugging more complex.  This level of indirection simply isn't present in a standard console application.

**4.  Asynchronous Operation and Task Completion:**

While `async/await` and `Task` facilitate asynchronous programming in both environments, the way exceptions are handled within the context of an Azure Function's lifecycle is crucial.  In a console application, an unhandled exception within an `async` method typically causes the main thread to terminate, providing a clear indication of the failure.  However, in Azure Functions, the asynchronous nature, combined with the serverless environment, can lead to exceptions being silently handled or logged without immediate program termination.  The function might complete its execution, reporting success, while underlying asynchronous operations have failed.


**Code Examples and Commentary:**

**Example 1: Simple Console Application**

```csharp
using System;
using System.Threading.Tasks;

public class ConsoleApp
{
    public static async Task Main(string[] args)
    {
        try
        {
            await DoSomethingAsync();
            Console.WriteLine("Operation completed successfully.");
        }
        catch (Exception ex)
        {
            Console.WriteLine($"An error occurred: {ex.Message}");
            Console.WriteLine(ex.StackTrace); //Provides detailed stack trace
        }
    }

    public static async Task DoSomethingAsync()
    {
        await Task.Delay(1000); // Simulate asynchronous operation
        throw new Exception("Something went wrong!");
    }
}
```

This console app demonstrates straightforward exception handling.  The `catch` block captures the exception, provides the message, and critically, displays the stack trace, enabling precise error identification.


**Example 2: Azure Function with Implicit Exception Handling**

```csharp
using System;
using System.Threading.Tasks;
using Microsoft.Azure.Functions.Worker;
using Microsoft.Extensions.Logging;

public class AzureFunction
{
    private readonly ILogger _logger;

    public AzureFunction(ILoggerFactory loggerFactory)
    {
        _logger = loggerFactory.CreateLogger<AzureFunction>();
    }

    [Function("MyFunction")]
    public async Task Run([TimerTrigger("0 */5 * * * *")] MyInfo myTimer, FunctionContext context)
    {
        try
        {
            await DoSomethingAsync();
            _logger.LogInformation($"C# Timer trigger function executed at: {DateTime.Now}");
        }
        catch (Exception ex)
        {
            _logger.LogError(ex, "An error occurred during function execution."); // Logging, but no direct program termination
        }
    }

    public async Task DoSomethingAsync()
    {
        await Task.Delay(1000);
        throw new Exception("Something went wrong!");
    }
}
```

This Azure Function utilizes the built-in logging mechanism.  The `try-catch` block handles exceptions, but the function continues its execution, potentially masking the failure. The detailed stack trace might be missing from the log entry, depending on the logging configuration.  This is a common scenario where subtle failures can go unnoticed.


**Example 3: Azure Function with Explicit Exception Handling and Retry**

```csharp
using System;
using System.Threading.Tasks;
using Microsoft.Azure.Functions.Worker;
using Microsoft.Azure.Functions.Worker.Http;
using Microsoft.Extensions.Logging;

public class AzureFunctionWithRetry
{
    private readonly ILogger _logger;

    public AzureFunctionWithRetry(ILoggerFactory loggerFactory)
    {
        _logger = loggerFactory.CreateLogger<AzureFunctionWithRetry>();
    }

    [Function("MyFunctionWithRetry")]
    public async Task<HttpResponseData> Run([HttpTrigger(AuthorizationLevel.Function, "get", "post")] HttpRequestData req, FunctionContext context)
    {
        var response = req.CreateResponse(System.Net.HttpStatusCode.OK);
        try
        {
            await DoSomethingAsync();
            await response.WriteStringAsync("Operation completed successfully.");
        }
        catch (Exception ex)
        {
            _logger.LogError(ex, "An error occurred. Retrying...");
            // Implement retry logic here (e.g., using Polly library)
            await response.WriteStringAsync($"An error occurred: {ex.Message}");
        }
        return response;
    }


    public async Task DoSomethingAsync()
    {
        await Task.Delay(1000);
        throw new Exception("Something went wrong!");
    }
}
```

This improved example introduces more robust error handling.  Instead of silently logging, the `catch` block informs the caller of the failure.  Furthermore, this is where you would strategically integrate a retry mechanism (using libraries like Polly) to handle transient errors, a crucial aspect of designing reliable Azure Functions.  Even with retries, careful monitoring and detailed exception logging remain vital.



**Resource Recommendations:**

* Microsoft Azure documentation on Functions.
* Comprehensive guides on exception handling in C#.
* Advanced topics on asynchronous programming with `async`/`await` and `Task`.
* Documentation on the Polly library for resilience and transient fault handling.


By understanding the architectural differences between console applications and the Azure Function runtime, developers can anticipate and effectively address asynchronous error scenarios, ensuring robust and reliable serverless applications.  The key is to adopt a proactive approach to exception handling, incorporating comprehensive logging, suitable retry mechanisms, and careful consideration of the function's execution context.
